Workbook
Name Slicer_Hospital_tier: #N/A

Sheet Customer Names
A1: Customer ID | B1: name
A2: Id1 | B2: Hawks, Ms. Kelly
A3: Id2 | B3: Lehner, Mr. Matthew D
A4: Id3 | B4: Lu, Mr. Phil
A5: Id4 | B5: Osborne, Ms. Kelsey
A6: Id5 | B6: Kadala, Ms. Kristyn
A7: Id6 | B7: Baker, Mr. Russell B.
A8: Id7 | B8: Macpherson, Mr. Scott
A9: Id8 | B9: Hallman, Mr. Stephen
A10: Id9 | B10: Moran, Mr. Patrick R.
A11: Id10 | B11: Benner, Ms. Brooke N.
A12: Id11 | B12: Fierro Vargas, Ms. Paola Andrea
... A2336: Id2335 | B2336: German, Mr. Aaron K

Sheet Medical Examinations
A1: Customer ID | B1: BMI | C1: HBA1C | D1: Heart Issues | E1: Any Transplants | F1: Cancer history | G1: NumberOfMajorSurgeries | H1: smoker
A2: Id1 | B2: 47.41 | C2: 7.47 | D2: No | E2: No | F2: No | G2: No major surgery | H2: yes
A3: Id2 | B3: 30.36 | C3: 5.77 | D3: No | E3: No | F3: No | G3: No major surgery | H3: yes
A4: Id4 | B4: 38.095 | C4: 6.05 | D4: No | E4: No | F4: No | G4: No major surgery | H4: yes
A5: Id5 | B5: 35.53 | C5: 5.45 | D5: No | E5: No | F5: No | G5: No major surgery | H5: yes
A6: Id6 | B6: 32.8 | C6: 6.59 | D6: No | E6: No | F6: No | G6: No major surgery | H6: yes
A7: Id7 | B7: 36.4 | C7: 6.07 | D7: No | E7: No | F7: No | G7: No major surgery | H7: yes
A8: Id8 | B8: 36.96 | C8: 7.93 | D8: No | E8: No | F8: No | G8: 3 | H8: yes
A9: Id10 | B9: 38.06 | C9: 10.79 | D9: No | E9: No | F9: No | G9: No major surgery | H9: yes
A10: Id12 | B10: 42.13 | C10: 11.9 | D10: No | E10: No | F10: No | G10: No major surgery | H10: yes
A11: Id13 | B11: 40.92 | C11: 8.41 | D11: No | E11: No | F11: No | G11: No major surgery | H11: yes
A12: Id14 | B12: 40.565 | C12: 7.02 | D12: No | E12: No | F12: No | G12: No major surgery | H12: yes
A13: Id16 | B13: 39.9 | C13: 11.32 | D13: No | E13: No | F13: No | G13: No major surgery | H13: yes
A14: Id17 | B14: 33.8 | C14: 7.67 | D14: No | E14: No | F14: No | G14: 3 | H14: yes
A15: Id20 | B15: 42.9 | C15: 11.41 | D15: No | E15: No | F15: No | G15: No major surgery | H15: yes
A16: Id23 | B16: 31.3 | C16: 11.38 | D16: No | E16: No | F16: No | G16: 3 | H16: yes
A17: Id26 | B17: 33.88 | C17: 7.01 | D17: No | E17: No | F17: No | G17: 3 | H17: yes
A18: Id27 | B18: 30.875 | C18: 11.88 | D18: No | E18: No | F18: No | G18: No major surgery | H18: yes
A19: Id30 | B19: 37.05 | C19: 8.44 | D19: No | E19: No | F19: No | G19: No major surgery | H19: yes
A20: Id31 | B20: 43.89 | C20: 8.71 | D20: No | E20: No | F20: No | G20: No major surgery | H20: yes
A21: Id33 | B21: 31.35 | C21: 6.86 | D21: No | E21: No | F21: No | G21: No major surgery | H21: yes
A22: Id35 | B22: 46.2 | C22: 6.09 | D22: No | E22: No | F22: Yes | G22: 1 | H22: yes
A23: Id36 | B23: 32.015 | C23: 11.75 | D23: No | E23: No | F23: No | G23: No major surgery | H23: yes
A24: Id37 | B24: 40.565 | C24: 7.37 | D24: No | E24: No | F24: No | G24: No major surgery | H24: yes
A25: Id38 | B25: 32.45 | C25: 11.91 | D25: No | E25: No | F25: No | G25: No major surgery | H25: yes
A26: Id39 | B26: 34.96 | C26: 6.52 | D26: No | E26: No | F26: No | G26: No major surgery | H26: yes
A27: Id40 | B27: 35.5 | C27: 5.14 | D27: No | E27: No | F27: Yes | G27: 1 | H27: yes
A28: Id41 | B28: 52.58 | C28: 4.19 | D28: No | E28: yes | F28: No | G28: 1 | H28: yes
A29: Id43 | B29: 38.06 | C29: 6.98 | D29: No | E29: No | F29: No | G29: No major surgery | H29: yes
A30: Id44 | B30: 34.21 | C30: 8.34 | D30: No | E30: No | F30: No | G30: No major surgery | H30: yes
A31: Id48 | B31: 40.37 | C31: 4.47 | D31: No | E31: No | F31: No | G31: No major surgery | H31: yes
A32: Id52 | B32: 31.16 | C32: 9.34 | D32: No | E32: No | F32: No | G32: No major surgery | H32: yes
A33: Id54 | B33: 51.93 | C33: 11.05 | D33: No | E33: No | F33: No | G33: No major surgery | H33: yes
A34: Id55 | B34: 38.95 | C34: 11.95 | D34: No | E34: No | F34: No | G34: No major surgery | H34: yes
A35: Id57 | B35: 34.2 | C35: 5.75 | D35: No | E35: No | F35: No | G35: 2 | H35: yes
A36: Id58 | B36: 50.63 | C36: 11.89 | D36: No | E36: No | F36: No | G36: No major surgery | H36: yes
A37: Id59 | B37: 36.48 | C37: 6.2 | D37: No | E37: No | F37: No | G37: No major surgery | H37: yes
A38: Id60 | B38: 54.82 | C38: 10.61 | D38: No | E38: No | F38: No | G38: No major surgery | H38: yes
A39: Id61 | B39: 38.06 | C39: 6.04 | D39: No | E39: No | F39: Yes | G39: 1 | H39: yes
A40: Id63 | B40: 52.06 | C40: 11.47 | D40: No | E40: No | F40: No | G40: No major surgery | H40: yes
...

Sheet Hospitalisation Details
A1: Customer ID | B1: year | C1: month | D1: date | E1: children | F1: charges | G1: Hospital tier | H1: City tier | I1: State ID
A2: Id2335 | B2: 1992 | C2: Jul | D2: 9 | E2: 0 | F2: 563.84 | G2: tier - 2 | H2: tier - 3 | I2: R1013
A3: Id2334 | B3: 1992 | C3: Nov | D3: 30 | E3: 0 | F3: 570.62 | G3: tier - 2 | H3: tier - 1 | I3: R1013
A4: Id2333 | B4: 1993 | C4: Jun | D4: 30 | E4: 0 | F4: 600 | G4: tier - 2 | H4: tier - 1 | I4: R1013
A5: Id2332 | B5: 1992 | C5: Sep | D5: 13 | E5: 0 | F5: 604.54 | G5: tier - 3 | H5: tier - 3 | I5: R1013
A6: Id2331 | B6: 1998 | C6: Jul | D6: 27 | E6: 0 | F6: 637.26 | G6: tier - 3 | H6: tier - 3 | I6: R1013
A7: Id2330 | B7: 2001 | C7: Nov | D7: 20 | E7: 0 | F7: 646.14 | G7: tier - 3 | H7: tier - 3 | I7: R1012
A8: Id2329 | B8: 1993 | C8: Jun | D8: 1 | E8: 0 | F8: 650 | G8: tier - 3 | H8: tier - 3 | I8: R1013
A9: Id2328 | B9: 1995 | C9: Jul | D9: 4 | E9: 0 | F9: 650 | G9: tier - 3 | H9: tier - 3 | I9: R1013
A10: Id2327 | B10: 2002 | C10: Nov | D10: 29 | E10: 0 | F10: 668 | G10: tier - 3 | H10: tier - 2 | I10: R1012
A11: Id2326 | B11: 1997 | C11: Nov | D11: 9 | E11: 0 | F11: 670 | G11: tier - 3 | H11: tier - 3 | I11: R1013
A12: Id2325 | B12: 2001 | C12: Sep | D12: 12 | E12: 0 | F12: 687.54 | G12: tier - 3 | H12: tier - 2 | I12: R1013
A13: Id2324 | B13: 1999 | C13: Dec | D13: 26 | E13: 0 | F13: 700 | G13: unknown | H13: tier - 3 | I13: R1013
... A2344: Id1 | B2344: 1968 | C2344: Oct | D2344: 12 | E2344: 0 | F2344: 63770.43 | G2344: tier - 1 | H2344: tier - 3 | I2344: R1013

Sheet Data cleaning
A1: Customer ID | B1: BMI | C1: HBA1C | D1: Heart Issues | E1: Any Transplants | F1: Cancer history | G1: NumberOfMajorSurgeries | H1: smoker | I1: Customer ID | J1: year | L1: month | M1: blank with sep | N1: date | O1: children | P1: charges | Q1: Hospital tier | R1: City tier | S1: State ID | U1: Check for the number of missing values marked with '?' in each column of the “Medical Examinations” Table and "Hospitalization Details" Table. | AI1: =COUNTBLANK(A1:S2344) -> 82
A2: Id1 | B2: 47.41 | C2: 7.47 | D2: No | E2: No | F2: No | G2: No major surgery | H2: yes | I2: Id2335 | J2: 1992 | K2: =IF(ISBLANK(J2),AVERAGE(J2:J7),J2) -> 1992 | L2: Jul | M2: =IF(ISBLANK(L2),"sep",L2) -> Jul | N2: 9 | O2: 0 | P2: 563.84 | Q2: tier - 2 | R2: tier - 3 | S2: R1013 | T2: =IF(ISBLANK(S2),"unknown",S2) -> R1013
A3: Id2 | B3: 30.36 | C3: 5.77 | D3: No | E3: No | F3: No | G3: No major surgery | H3: yes | I3: Id2334 | J3: 1992 | K3: =IF(ISBLANK(J3),AVERAGE(J3:J8),J3) -> 1992 | L3: Nov | M3: =IF(ISBLANK(L3),"sep",L3) -> Nov | N3: 30 | O3: 0 | P3: 570.62 | Q3: tier - 2 | R3: tier - 1 | S3: R1013 | T3: =IF(ISBLANK(S3),"unknown",S3) -> R1013
A4: Id3 | B4: 34.485 | C4: 11.87 | D4: yes | E4: No | F4: No | G4: 2 | H4: yes | I4: Id2333 | J4: 1993 | K4: =IF(ISBLANK(J4),AVERAGE(J4:J9),J4) -> 1993 | L4: Jun | M4: =IF(ISBLANK(L4),"sep",L4) -> Jun | N4: 30 | O4: 0 | P4: 600 | Q4: tier - 2 | R4: tier - 1 | S4: R1013 | T4: =IF(ISBLANK(S4),"unknown",S4) -> R1013
A5: Id4 | B5: 38.095 | C5: 6.05 | D5: No | E5: No | F5: No | G5: No major surgery | H5: yes | I5: Id2332 | J5: 1992 | K5: =IF(ISBLANK(J5),AVERAGE(J5:J10),J5) -> 1992 | L5: Sep | M5: =IF(ISBLANK(L5),"sep",L5) -> Sep | N5: 13 | O5: 0 | P5: 604.54 | Q5: tier - 3 | R5: tier - 3 | S5: R1013 | T5: =IF(ISBLANK(S5),"unknown",S5) -> R1013
A6: Id5 | B6: 35.53 | C6: 5.45 | D6: No | E6: No | F6: No | G6: No major surgery | H6: yes | I6: Id2331 | J6: 1998 | K6: =IF(ISBLANK(J6),AVERAGE(J6:J11),J6) -> 1998 | L6: Jul | M6: =IF(ISBLANK(L6),"sep",L6) -> Jul | N6: 27 | O6: 0 | P6: 637.26 | Q6: tier - 3 | R6: tier - 3 | S6: R1013 | T6: =IF(ISBLANK(S6),"unknown",S6) -> R1013
A7: Id6 | B7: 32.8 | C7: 6.59 | D7: No | E7: No | F7: No | G7: No major surgery | H7: yes | I7: Id2330 | J7: 2001 | K7: =IF(ISBLANK(J7),AVERAGE(J7:J12),J7) -> 2001 | L7: Nov | M7: =IF(ISBLANK(L7),"sep",L7) -> Nov | N7: 20 | O7: 0 | P7: 646.14 | Q7: tier - 3 | R7: tier - 3 | S7: R1012 | T7: =IF(ISBLANK(S7),"unknown",S7) -> R1012
A8: Id7 | B8: 36.4 | C8: 6.07 | D8: No | E8: No | F8: No | G8: No major surgery | H8: yes | I8: Id2329 | J8: 1993 | K8: =IF(ISBLANK(J8),AVERAGE(J8:J13),J8) -> 1993 | L8: Jun | M8: =IF(ISBLANK(L8),"sep",L8) -> Jun | N8: 1 | O8: 0 | P8: 650 | Q8: tier - 3 | R8: tier - 3 | S8: R1013 | T8: =IF(ISBLANK(S8),"unknown",S8) -> R1013
A9: Id8 | B9: 36.96 | C9: 7.93 | D9: No | E9: No | F9: No | G9: 3 | H9: yes | I9: Id2328 | J9: 1995 | K9: =IF(ISBLANK(J9),AVERAGE(J9:J14),J9) -> 1995 | L9: Jul | M9: =IF(ISBLANK(L9),"sep",L9) -> Jul | N9: 4 | O9: 0 | P9: 650 | Q9: tier - 3 | R9: tier - 3 | S9: R1013 | T9: =IF(ISBLANK(S9),"unknown",S9) -> R1013
A10: Id9 | B10: 41.14 | C10: 9.58 | D10: yes | E10: No | F10: Yes | G10: 1 | H10: yes | I10: Id2327 | J10: 2002 | K10: =IF(ISBLANK(J10),AVERAGE(J10:J15),J10) -> 2002 | L10: Nov | M10: =IF(ISBLANK(L10),"sep",L10) -> Nov | N10: 29 | O10: 0 | P10: 668 | Q10: tier - 3 | R10: tier - 2 | S10: R1012 | T10: =IF(ISBLANK(S10),"unknown",S10) -> R1012
A11: Id10 | B11: 38.06 | C11: 10.79 | D11: No | E11: No | F11: No | G11: No major surgery | H11: yes | I11: Id2326 | J11: 1997 | K11: =IF(ISBLANK(J11),AVERAGE(J11:J16),J11) -> 1997 | L11: Nov | M11: =IF(ISBLANK(L11),"sep",L11) -> Nov | N11: 9 | O11: 0 | P11: 670 | Q11: tier - 3 | R11: tier - 3 | S11: R1013 | T11: =IF(ISBLANK(S11),"unknown",S11) -> R1013
A12: Id11 | B12: 37.7 | C12: 5.96 | D12: yes | E12: No | F12: No | G12: 2 | H12: yes | I12: Id2325 | J12: 2001 | K12: =IF(ISBLANK(J12),AVERAGE(J12:J17),J12) -> 2001 | L12: Sep | M12: =IF(ISBLANK(L12),"sep",L12) -> Sep | N12: 12 | O12: 0 | P12: 687.54 | Q12: tier - 3 | R12: tier - 2 | S12: R1013 | T12: =IF(ISBLANK(S12),"unknown",S12) -> R1013
A13: Id12 | B13: 42.13 | C13: 11.9 | D13: No | E13: No | F13: No | G13: No major surgery | H13: yes | I13: Id2324 | J13: 1999 | K13: =IF(ISBLANK(J13),AVERAGE(J13:J18),J13) -> 1999 | L13: Dec | M13: =IF(ISBLANK(L13),"sep",L13) -> Dec | N13: 26 | O13: 0 | P13: 700 | R13: tier - 3 | S13: R1013 | T13: =IF(ISBLANK(S13),"unknown",S13) -> R1013
A14: Id13 | B14: 40.92 | C14: 8.41 | D14: No | E14: No | F14: No | G14: No major surgery | H14: yes | I14: Id2323 | J14: 1999 | K14: =IF(ISBLANK(J14),AVERAGE(J14:J19),J14) -> 1999 | L14: Dec | M14: =IF(ISBLANK(L14),"sep",L14) -> Dec | N14: 14 | O14: 0 | P14: 722.99 | Q14: tier - 3 | R14: tier - 1 | S14: R1013 | T14: =IF(ISBLANK(S14),"unknown",S14) -> R1013
A15: Id14 | B15: 40.565 | C15: 7.02 | D15: No | E15: No | F15: No | G15: No major surgery | H15: yes | I15: Id2322 | J15: 2002 | K15: =IF(ISBLANK(J15),AVERAGE(J15:J20),J15) -> 2002 | M15: =IF(ISBLANK(L15),"sep",L15) -> sep | N15: 19 | O15: 0 | P15: 750 | Q15: tier - 3 | R15: tier - 1 | S15: R1012 | T15: =IF(ISBLANK(S15),"unknown",S15) -> R1012
A16: Id15 | B16: 36.385 | C16: 7.59 | D16: yes | E16: No | F16: No | G16: 2 | H16: yes | I16: Id2321 | J16: 1993 | K16: =IF(ISBLANK(J16),AVERAGE(J16:J21),J16) -> 1993 | L16: Aug | M16: =IF(ISBLANK(L16),"sep",L16) -> Aug | N16: 9 | O16: 0 | P16: 760 | Q16: tier - 3 | R16: tier - 1 | S16: R1013 | T16: =IF(ISBLANK(S16),"unknown",S16) -> R1013
A17: Id16 | B17: 39.9 | C17: 11.32 | D17: No | E17: No | F17: No | G17: No major surgery | H17: yes | I17: Id2320 | J17: 1996 | K17: =IF(ISBLANK(J17),AVERAGE(J17:J22),J17) -> 1996 | L17: Oct | M17: =IF(ISBLANK(L17),"sep",L17) -> Oct | N17: 22 | O17: 0 | P17: 760 | Q17: tier - 3 | R17: tier - 3 | S17: R1013 | T17: =IF(ISBLANK(S17),"unknown",S17) -> R1013
A18: Id17 | B18: 33.8 | C18: 7.67 | D18: No | E18: No | F18: No | G18: 3 | H18: yes | I18: Id2319 | J18: 1993 | K18: =IF(ISBLANK(J18),AVERAGE(J18:J23),J18) -> 1993 | L18: Jun | M18: =IF(ISBLANK(L18),"sep",L18) -> Jun | N18: 28 | O18: 0 | P18: 770 | Q18: tier - 3 | R18: tier - 3 | S18: R1013 | T18: =IF(ISBLANK(S18),"unknown",S18) -> R1013
A19: Id18 | B19: 36.765 | C19: 7.29 | D19: yes | E19: No | F19: Yes | G19: 1 | H19: yes | I19: Id2318 | J19: 1996 | K19: =IF(ISBLANK(J19),AVERAGE(J19:J24),J19) -> 1996 | M19: =IF(ISBLANK(L19),"sep",L19) -> sep | N19: 18 | O19: 0 | P19: 770.38 | Q19: tier - 3 | S19: R1012 | T19: =IF(ISBLANK(S19),"unknown",S19) -> R1012
A20: Id19 | B20: 36.955 | C20: 4.72 | D20: yes | E20: No | F20: No | G20: 1 | H20: yes | I20: Id2317 | J20: 1995 | K20: =IF(ISBLANK(J20),AVERAGE(J20:J25),J20) -> 1995 | L20: Dec | M20: =IF(ISBLANK(L20),"sep",L20) -> Dec | N20: 7 | O20: 0 | P20: 773.54 | Q20: tier - 3 | R20: tier - 2 | S20: R1013 | T20: =IF(ISBLANK(S20),"unknown",S20) -> R1013
A21: Id20 | B21: 42.9 | C21: 11.41 | D21: No | E21: No | F21: No | G21: No major surgery | H21: yes | I21: Id2316 | J21: 2004 | K21: =IF(ISBLANK(J21),AVERAGE(J21:J26),J21) -> 2004 | L21: Oct | M21: =IF(ISBLANK(L21),"sep",L21) -> Oct | N21: 7 | O21: 0 | P21: 830.52 | Q21: tier - 3 | R21: tier - 2 | S21: R1011 | T21: =IF(ISBLANK(S21),"unknown",S21) -> R1011
A22: Id21 | B22: 36.3 | C22: 11.5 | D22: yes | E22: No | F22: No | G22: 2 | H22: yes | I22: Id2315 | J22: 2000 | K22: =IF(ISBLANK(J22),AVERAGE(J22:J27),J22) -> 2000 | L22: Nov | M22: =IF(ISBLANK(L22),"sep",L22) -> Nov | N22: 18 | O22: 0 | P22: 865.41 | Q22: tier - 3 | R22: tier - 1 | S22: R1013 | T22: =IF(ISBLANK(S22),"unknown",S22) -> R1013
A23: Id22 | B23: 32.2 | C23: 6.22 | D23: yes | E23: No | F23: No | G23: 2 | H23: yes | I23: Id2314 | J23: 1993 | K23: =IF(ISBLANK(J23),AVERAGE(J23:J28),J23) -> 1993 | L23: Nov | M23: =IF(ISBLANK(L23),"sep",L23) -> Nov | N23: 27 | O23: 0 | P23: 896.21 | Q23: tier - 3 | R23: tier - 1 | S23: R1013 | T23: =IF(ISBLANK(S23),"unknown",S23) -> R1013
A24: Id23 | B24: 31.3 | C24: 11.38 | D24: No | E24: No | F24: No | G24: 3 | H24: yes | I24: Id2313 | J24: 1994 | K24: =IF(ISBLANK(J24),AVERAGE(J24:J29),J24) -> 1994 | L24: Oct | M24: =IF(ISBLANK(L24),"sep",L24) -> Oct | N24: 30 | O24: 0 | P24: 915.07 | Q24: tier - 3 | R24: tier - 1 | S24: R1013 | T24: =IF(ISBLANK(S24),"unknown",S24) -> R1013
A25: Id24 | B25: 41.8 | C25: 7.89 | D25: yes | E25: No | F25: No | G25: 2 | H25: yes | I25: Id2312 | J25: 1995 | K25: =IF(ISBLANK(J25),AVERAGE(J25:J30),J25) -> 1995 | L25: Oct | M25: =IF(ISBLANK(L25),"sep",L25) -> Oct | N25: 28 | O25: 0 | P25: 928.59 | Q25: tier - 3 | R25: tier - 1 | S25: R1013 | T25: =IF(ISBLANK(S25),"unknown",S25) -> R1013
A26: Id25 | B26: 35.09 | C26: 4.38 | D26: yes | E26: No | F26: No | G26: 2 | H26: yes | I26: Id2311 | J26: 2001 | K26: =IF(ISBLANK(J26),AVERAGE(J26:J31),J26) -> 2001 | L26: Aug | M26: =IF(ISBLANK(L26),"sep",L26) -> Aug | N26: 19 | O26: 0 | P26: 964.71 | Q26: tier - 3 | R26: tier - 2 | S26: R1013 | T26: =IF(ISBLANK(S26),"unknown",S26) -> R1013
A27: Id26 | B27: 33.88 | C27: 7.01 | D27: No | E27: No | F27: No | G27: 3 | H27: yes | I27: Id2310 | J27: 1994 | K27: =IF(ISBLANK(J27),AVERAGE(J27:J32),J27) -> 1994 | L27: Nov | M27: =IF(ISBLANK(L27),"sep",L27) -> Nov | N27: 22 | O27: 0 | P27: 1006.65 | Q27: tier - 3 | R27: tier - 2 | S27: R1013 | T27: =IF(ISBLANK(S27),"unknown",S27) -> R1013
A28: Id27 | B28: 30.875 | C28: 11.88 | D28: No | E28: No | F28: No | G28: No major surgery | H28: yes | I28: Id2309 | J28: 2000 | K28: =IF(ISBLANK(J28),AVERAGE(J28:J33),J28) -> 2000 | L28: Oct | M28: =IF(ISBLANK(L28),"sep",L28) -> Oct | N28: 9 | O28: 0 | P28: 1012 | Q28: tier - 3 | R28: tier - 2 | S28: R1013 | T28: =IF(ISBLANK(S28),"unknown",S28) -> R1013
A29: Id28 | B29: 36.86 | C29: 5.19 | D29: yes | E29: No | F29: Yes | G29: 1 | H29: yes | I29: Id2308 | J29: 1999 | K29: =IF(ISBLANK(J29),AVERAGE(J29:J34),J29) -> 1999 | L29: Aug | M29: =IF(ISBLANK(L29),"sep",L29) -> Aug | N29: 5 | O29: 0 | P29: 1019 | Q29: tier - 3 | R29: tier - 2 | S29: R1013 | T29: =IF(ISBLANK(S29),"unknown",S29) -> R1013
A30: Id29 | B30: 35.86 | C30: 6.74 | D30: yes | E30: No | F30: No | G30: 2 | H30: yes | I30: Id2307 | J30: 1995 | K30: =IF(ISBLANK(J30),AVERAGE(J30:J35),J30) -> 1995 | L30: Oct | M30: =IF(ISBLANK(L30),"sep",L30) -> Oct | N30: 5 | O30: 0 | P30: 1033.74 | Q30: tier - 3 | R30: tier - 1 | S30: R1013 | T30: =IF(ISBLANK(S30),"unknown",S30) -> R1013
A31: Id30 | B31: 37.05 | C31: 8.44 | D31: No | E31: No | F31: No | G31: No major surgery | H31: yes | I31: Id2306 | J31: 1994 | K31: =IF(ISBLANK(J31),AVERAGE(J31:J36),J31) -> 1994 | L31: Nov | M31: =IF(ISBLANK(L31),"sep",L31) -> Nov | N31: 17 | O31: 0 | P31: 1044 | Q31: tier - 3 | R31: tier - 2 | S31: R1013 | T31: =IF(ISBLANK(S31),"unknown",S31) -> R1013
A32: Id31 | B32: 43.89 | C32: 8.71 | D32: No | E32: No | F32: No | G32: No major surgery | H32: yes | I32: Id2305 | J32: 2002 | K32: =IF(ISBLANK(J32),AVERAGE(J32:J37),J32) -> 2002 | L32: Jul | M32: =IF(ISBLANK(L32),"sep",L32) -> Jul | N32: 20 | O32: 0 | P32: 1047 | Q32: tier - 3 | R32: tier - 1 | S32: R1013 | T32: =IF(ISBLANK(S32),"unknown",S32) -> R1013
A33: Id32 | B33: 42.35 | C33: 5.08 | D33: yes | E33: No | F33: No | G33: No major surgery | H33: yes | I33: Id2304 | J33: 2002 | K33: =IF(ISBLANK(J33),AVERAGE(J33:J38),J33) -> 2002 | L33: Jul | M33: =IF(ISBLANK(L33),"sep",L33) -> Jul | N33: 1 | O33: 0 | P33: 1049 | Q33: tier - 3 | R33: tier - 2 | S33: R1012 | T33: =IF(ISBLANK(S33),"unknown",S33) -> R1012
A34: Id33 | B34: 31.35 | C34: 6.86 | D34: No | E34: No | F34: No | G34: No major surgery | H34: yes | I34: Id2303 | J34: 1995 | K34: =IF(ISBLANK(J34),AVERAGE(J34:J39),J34) -> 1995 | L34: Jun | M34: =IF(ISBLANK(L34),"sep",L34) -> Jun | N34: 1 | O34: 0 | P34: 1056 | Q34: tier - 3 | R34: tier - 2 | S34: R1013 | T34: =IF(ISBLANK(S34),"unknown",S34) -> R1013
A35: Id34 | B35: 47.6 | C35: 5.95 | D35: yes | E35: No | F35: No | G35: No major surgery | H35: yes | I35: Id2302 | J35: 1993 | K35: =IF(ISBLANK(J35),AVERAGE(J35:J40),J35) -> 1993 | L35: Sep | M35: =IF(ISBLANK(L35),"sep",L35) -> Sep | N35: 28 | O35: 0 | P35: 1068 | Q35: tier - 3 | R35: tier - 1 | S35: R1013 | T35: =IF(ISBLANK(S35),"unknown",S35) -> R1013
A36: Id35 | B36: 46.2 | C36: 6.09 | D36: No | E36: No | F36: Yes | G36: 1 | H36: yes | I36: Id2301 | J36: 2004 | K36: =IF(ISBLANK(J36),AVERAGE(J36:J41),J36) -> 2004 | L36: Aug | M36: =IF(ISBLANK(L36),"sep",L36) -> Aug | N36: 24 | O36: 0 | P36: 1070 | Q36: tier - 3 | R36: tier - 3 | S36: R1013 | T36: =IF(ISBLANK(S36),"unknown",S36) -> R1013
A37: Id36 | B37: 32.015 | C37: 11.75 | D37: No | E37: No | F37: No | G37: No major surgery | H37: yes | I37: Id2300 | J37: 1997 | K37: =IF(ISBLANK(J37),AVERAGE(J37:J42),J37) -> 1997 | L37: Aug | M37: =IF(ISBLANK(L37),"sep",L37) -> Aug | N37: 13 | O37: 0 | P37: 1071 | Q37: tier - 3 | R37: tier - 3 | S37: R1013 | T37: =IF(ISBLANK(S37),"unknown",S37) -> R1013
A38: Id37 | B38: 40.565 | C38: 7.37 | D38: No | E38: No | F38: No | G38: No major surgery | H38: yes | I38: Id2299 | J38: 1998 | K38: =IF(ISBLANK(J38),AVERAGE(J38:J43),J38) -> 1998 | L38: Dec | M38: =IF(ISBLANK(L38),"sep",L38) -> Dec | N38: 26 | O38: 0 | P38: 1082 | Q38: tier - 3 | R38: tier - 2 | S38: R1013 | T38: =IF(ISBLANK(S38),"unknown",S38) -> R1013
A39: Id38 | B39: 32.45 | C39: 11.91 | D39: No | E39: No | F39: No | G39: No major surgery | H39: yes | I39: Id2298 | J39: 2002 | K39: =IF(ISBLANK(J39),AVERAGE(J39:J44),J39) -> 2002 | L39: Aug | M39: =IF(ISBLANK(L39),"sep",L39) -> Aug | N39: 13 | O39: 0 | P39: 1086 | Q39: tier - 3 | R39: tier - 3 | S39: R1013 | T39: =IF(ISBLANK(S39),"unknown",S39) -> R1013
A40: Id39 | B40: 34.96 | C40: 6.52 | D40: No | E40: No | F40: No | G40: No major surgery | H40: yes | I40: Id2297 | J40: 2004 | K40: =IF(ISBLANK(J40),AVERAGE(J40:J45),J40) -> 2004 | L40: Nov | M40: =IF(ISBLANK(L40),"sep",L40) -> Nov | N40: 12 | O40: 0 | P40: 1121.87 | Q40: tier - 3 | R40: tier - 1 | S40: R1013 | T40: =IF(ISBLANK(S40),"unknown",S40) -> R1013
...

Sheet Data Transformation
A1: Customer ID | B1: name | G1: NumberOfMajorSurgeries | H1: Heart Issues | I1: smoker | J1: BMI | K1: weight status | L1: HBA1C | M1: Diabetes Status | N1: year | O1: month | P1: date | Q1: Date of Birth | R1: customer age | S1: charges
A2: Id1 | B2: Hawks, Ms. Kelly | C2: Ms | D2: Kelly | E2: Hawks | G2: 0 | H2: No | I2: yes | J2: 47.41 | K2: {=_xlfn.IFS(J2<18.5,"underweight",J2<25,"normal weight",J2<30,"overweight",J2>30,"obesity")} -> obesity | L2: 7.47 | M2: {=_xlfn.IFS(L2<5.7,"Normal",L2<6.5,"Prediabetes",L2>6.5,"Diabetes")} -> Diabetes | N2: 1992 | O2: Jul | P2: 9 | Q2: =P2&"-"&O2&"-"&N2 -> 9-Jul-1992 | R2: =DATEDIF(Q2,"8-6-2023","y") -> 31 | S2: 563.84
A3: Id2 | B3: Lehner, Mr. Matthew D | C3: Mr | D3: Matthew D | E3: Lehner | G3: 0 | H3: No | I3: yes | J3: 30.36 | K3: {=_xlfn.IFS(J3<18.5,"underweight",J3<25,"normal weight",J3<30,"overweight",J3>30,"obesity")} -> obesity | L3: 5.77 | M3: {=_xlfn.IFS(L3<5.7,"Normal",L3<6.5,"Prediabetes",L3>6.5,"Diabetes")} -> Prediabetes | N3: 1992 | O3: Nov | P3: 30 | Q3: =P3&"-"&O3&"-"&N3 -> 30-Nov-1992 | R3: =DATEDIF(Q3,"8-6-2023","y") -> 30 | S3: 570.62
A4: Id3 | B4: Lu, Mr. Phil | C4: Mr | D4: Phil | E4: Lu | G4: 2 | H4: No | I4: yes | J4: 38.095 | K4: {=_xlfn.IFS(J4<18.5,"underweight",J4<25,"normal weight",J4<30,"overweight",J4>30,"obesity")} -> obesity | L4: 6.05 | M4: {=_xlfn.IFS(L4<5.7,"Normal",L4<6.5,"Prediabetes",L4>6.5,"Diabetes")} -> Prediabetes | N4: 1993 | O4: Jun | P4: 30 | Q4: =P4&"-"&O4&"-"&N4 -> 30-Jun-1993 | R4: =DATEDIF(Q4,"8-6-2023","y") -> 30 | S4: 600
A5: Id4 | B5: Osborne, Ms. Kelsey | C5: Ms | D5: Kelsey | E5: Osborne | G5: 0 | H5: No | I5: yes | J5: 35.53 | K5: {=_xlfn.IFS(J5<18.5,"underweight",J5<25,"normal weight",J5<30,"overweight",J5>30,"obesity")} -> obesity | L5: 5.45 | M5: {=_xlfn.IFS(L5<5.7,"Normal",L5<6.5,"Prediabetes",L5>6.5,"Diabetes")} -> Normal | N5: 1992 | O5: Sep | P5: 13 | Q5: =P5&"-"&O5&"-"&N5 -> 13-Sep-1992 | R5: =DATEDIF(Q5,"8-6-2023","y") -> 30 | S5: 604.54
A6: Id5 | B6: Kadala, Ms. Kristyn | C6: Ms | D6: Kristyn | E6: Kadala | G6: 0 | H6: No | I6: yes | J6: 32.8 | K6: {=_xlfn.IFS(J6<18.5,"underweight",J6<25,"normal weight",J6<30,"overweight",J6>30,"obesity")} -> obesity | L6: 6.59 | M6: {=_xlfn.IFS(L6<5.7,"Normal",L6<6.5,"Prediabetes",L6>6.5,"Diabetes")} -> Diabetes | N6: 1998 | O6: Jul | P6: 27 | Q6: =P6&"-"&O6&"-"&N6 -> 27-Jul-1998 | R6: =DATEDIF(Q6,"8-6-2023","y") -> 25 | S6: 637.26
A7: Id6 | B7: Baker, Mr. Russell B. | C7: Mr | D7: Russell B | E7: Baker | G7: 0 | H7: No | I7: yes | J7: 36.4 | K7: {=_xlfn.IFS(J7<18.5,"underweight",J7<25,"normal weight",J7<30,"overweight",J7>30,"obesity")} -> obesity | L7: 6.07 | M7: {=_xlfn.IFS(L7<5.7,"Normal",L7<6.5,"Prediabetes",L7>6.5,"Diabetes")} -> Prediabetes | N7: 2001 | O7: Nov | P7: 20 | Q7: =P7&"-"&O7&"-"&N7 -> 20-Nov-2001 | R7: =DATEDIF(Q7,"8-6-2023","y") -> 21 | S7: 646.14
A8: Id7 | B8: Macpherson, Mr. Scott | C8: Mr | D8: Scott | E8: Macpherson | G8: 0 | H8: No | I8: yes | J8: 36.96 | K8: {=_xlfn.IFS(J8<18.5,"underweight",J8<25,"normal weight",J8<30,"overweight",J8>30,"obesity")} -> obesity | L8: 7.93 | M8: {=_xlfn.IFS(L8<5.7,"Normal",L8<6.5,"Prediabetes",L8>6.5,"Diabetes")} -> Diabetes | N8: 1993 | O8: Jun | P8: 1 | Q8: =P8&"-"&O8&"-"&N8 -> 1-Jun-1993 | R8: =DATEDIF(Q8,"8-6-2023","y") -> 30 | S8: 650
A9: Id8 | B9: Hallman, Mr. Stephen | C9: Mr | D9: Stephen | E9: Hallman | G9: 3 | H9: No | I9: yes | J9: 38.06 | K9: {=_xlfn.IFS(J9<18.5,"underweight",J9<25,"normal weight",J9<30,"overweight",J9>30,"obesity")} -> obesity | L9: 10.79 | M9: {=_xlfn.IFS(L9<5.7,"Normal",L9<6.5,"Prediabetes",L9>6.5,"Diabetes")} -> Diabetes | N9: 1995 | O9: Jul | P9: 4 | Q9: =P9&"-"&O9&"-"&N9 -> 4-Jul-1995 | R9: =DATEDIF(Q9,"8-6-2023","y") -> 28 | S9: 650
A10: Id9 | B10: Moran, Mr. Patrick R. | C10: Mr | D10: Patrick R | E10: Moran | G10: 1 | H10: No | I10: yes | J10: 42.13 | K10: {=_xlfn.IFS(J10<18.5,"underweight",J10<25,"normal weight",J10<30,"overweight",J10>30,"obesity")} -> obesity | L10: 11.9 | M10: {=_xlfn.IFS(L10<5.7,"Normal",L10<6.5,"Prediabetes",L10>6.5,"Diabetes")} -> Diabetes | N10: 2002 | O10: Nov | P10: 29 | Q10: =P10&"-"&O10&"-"&N10 -> 29-Nov-2002 | R10: =DATEDIF(Q10,"8-6-2023","y") -> 20 | S10: 668
A11: Id10 | B11: Benner, Ms. Brooke N. | C11: Ms | D11: Brooke N | E11: Benner | G11: 0 | H11: No | I11: yes | J11: 40.92 | K11: {=_xlfn.IFS(J11<18.5,"underweight",J11<25,"normal weight",J11<30,"overweight",J11>30,"obesity")} -> obesity | L11: 8.41 | M11: {=_xlfn.IFS(L11<5.7,"Normal",L11<6.5,"Prediabetes",L11>6.5,"Diabetes")} -> Diabetes | N11: 1997 | O11: Nov | P11: 9 | Q11: =P11&"-"&O11&"-"&N11 -> 9-Nov-1997 | R11: =DATEDIF(Q11,"8-6-2023","y") -> 25 | S11: 670
A12: Id11 | B12: Fierro Vargas, Ms. Paola Andrea | C12: Ms | D12: Paola Andrea | E12: Fierro Vargas | G12: 2 | H12: No | I12: yes | J12: 40.565 | K12: {=_xlfn.IFS(J12<18.5,"underweight",J12<25,"normal weight",J12<30,"overweight",J12>30,"obesity")} -> obesity | L12: 7.02 | M12: {=_xlfn.IFS(L12<5.7,"Normal",L12<6.5,"Prediabetes",L12>6.5,"Diabetes")} -> Diabetes | N12: 2001 | O12: Sep | P12: 12 | Q12: =P12&"-"&O12&"-"&N12 -> 12-Sep-2001 | R12: =DATEDIF(Q12,"8-6-2023","y") -> 21 | S12: 687.54
A13: Id12 | B13: Franz, Mr. David | C13: Mr | D13: David | E13: Franz | G13: 0 | H13: No | I13: yes | J13: 39.9 | K13: {=_xlfn.IFS(J13<18.5,"underweight",J13<25,"normal weight",J13<30,"overweight",J13>30,"obesity")} -> obesity | L13: 11.32 | M13: {=_xlfn.IFS(L13<5.7,"Normal",L13<6.5,"Prediabetes",L13>6.5,"Diabetes")} -> Diabetes | N13: 1999 | O13: Dec | P13: 26 | Q13: =P13&"-"&O13&"-"&N13 -> 26-Dec-1999 | R13: =DATEDIF(Q13,"8-6-2023","y") -> 23 | S13: 700
... A1050: Id1049 | B1050: Hempel, Ms. Alexandra | C1050: Ms | D1050: Alexandra | E1050: Hempel | G1050: 0 | H1050: No | I1050: No | J1050: 46.53 | K1050: {=_xlfn.IFS(J1050<18.5,"underweight",J1050<25,"normal weight",J1050<30,"overweight",J1050>30,"obesity")} -> obesity | L1050: 4.16 | M1050: {=_xlfn.IFS(L1050<5.7,"Normal",L1050<6.5,"Prediabetes",L1050>6.5,"Diabetes")} -> Normal | N1050: 1977 | O1050: Jul | P1050: 26 | Q1050: =P1050&"-"&O1050&"-"&N1050 -> 26-Jul-1977 | R1050: =DATEDIF(Q1050,"8-6-2023","y") -> 46 | S1050: 8527.53
A1051: Id1050 | B1051: McBroom, Ms. Tiffany | C1051: Ms | D1051: Tiffany | E1051: McBroom | G1051: 2 | H1051: No | I1051: No | J1051: 34.99 | K1051: {=_xlfn.IFS(J1051<18.5,"underweight",J1051<25,"normal weight",J1051<30,"overweight",J1051>30,"obesity")} -> obesity | L1051: 5.1 | M1051: {=_xlfn.IFS(L1051<5.7,"Normal",L1051<6.5,"Prediabetes",L1051>6.5,"Diabetes")} -> Normal | N1051: ? | O1051: Jul | P1051: 24 | Q1051: =P1051&"-"&O1051&"-"&N1051 -> 24-Jul-? | R1051: =DATEDIF(Q1051,"8-6-2023","y") -> #VALUE! | S1051: 8534.67
A1052: Id1051 | B1052: Yoo, Mrs. Rebecca J | C1052: Mrs | D1052: Rebecca J | E1052: Yoo | G1052: 0 | H1052: No | I1052: No | J1052: 17.05 | K1052: {=_xlfn.IFS(J1052<18.5,"underweight",J1052<25,"normal weight",J1052<30,"overweight",J1052>30,"obesity")} -> underweight | L1052: 5.3 | M1052: {=_xlfn.IFS(L1052<5.7,"Normal",L1052<6.5,"Prediabetes",L1052>6.5,"Diabetes")} -> Normal | N1052: 1981 | O1052: Dec | P1052: 27 | Q1052: =P1052&"-"&O1052&"-"&N1052 -> 27-Dec-1981 | R1052: =DATEDIF(Q1052,"8-6-2023","y") -> 41 | S1052: 8538.29
A1053: Id1052 | B1053: Rand, Mr. Austin T. | C1053: Mr | D1053: Austin T | E1053: Rand | G1053: 0 | H1053: No | I1053: No | J1053: 37.18 | K1053: {=_xlfn.IFS(J1053<18.5,"underweight",J1053<25,"normal weight",J1053<30,"overweight",J1053>30,"obesity")} -> obesity | L1053: 4.9 | M1053: {=_xlfn.IFS(L1053<5.7,"Normal",L1053<6.5,"Prediabetes",L1053>6.5,"Diabetes")} -> Normal | N1053: 1975 | O1053: Nov | P1053: 6 | Q1053: =P1053&"-"&O1053&"-"&N1053 -> 6-Nov-1975 | R1053: =DATEDIF(Q1053,"8-6-2023","y") -> 47 | S1053: 8539.67
A1054: Id1053 | B1054: Wolfe, Ms. Jamie T | C1054: Ms | D1054: Jamie T | E1054: Wolfe | G1054: 0 | H1054: No | I1054: No | J1054: 35.2 | K1054: {=_xlfn.IFS(J1054<18.5,"underweight",J1054<25,"normal weight",J1054<30,"overweight",J1054>30,"obesity")} -> obesity | L1054: 5.55 | M1054: {=_xlfn.IFS(L1054<5.7,"Normal",L1054<6.5,"Prediabetes",L1054>6.5,"Diabetes")} -> Normal | N1054: ? | O1054: Dec | P1054: 12 | Q1054: =P1054&"-"&O1054&"-"&N1054 -> 12-Dec-? | R1054: =DATEDIF(Q1054,"8-6-2023","y") -> #VALUE! | S1054: 8547.69
A1055: Id1054 | B1055: Vance, Mr. Matthew T. | C1055: Mr | D1055: Matthew T | E1055: Vance | G1055: 0 | H1055: No | I1055: No | J1055: 37.335 | K1055: {=_xlfn.IFS(J1055<18.5,"underweight",J1055<25,"normal weight",J1055<30,"overweight",J1055>30,"obesity")} -> obesity | L1055: 4.95 | M1055: {=_xlfn.IFS(L1055<5.7,"Normal",L1055<6.5,"Prediabetes",L1055>6.5,"Diabetes")} -> Normal | N1055: 1975 | O1055: Aug | P1055: 6 | Q1055: =P1055&"-"&O1055&"-"&N1055 -> 6-Aug-1975 | R1055: =DATEDIF(Q1055,"8-6-2023","y") -> 48 | S1055: 8551.35
A1056: Id1055 | B1056: Burnett, Mrs. Emily | C1056: Mrs | D1056: Emily | E1056: Burnett | G1056: 1 | H1056: No | I1056: No | J1056: 30.21 | K1056: {=_xlfn.IFS(J1056<18.5,"underweight",J1056<25,"normal weight",J1056<30,"overweight",J1056>30,"obesity")} -> obesity | L1056: 5.21 | M1056: {=_xlfn.IFS(L1056<5.7,"Normal",L1056<6.5,"Prediabetes",L1056>6.5,"Diabetes")} -> Normal | N1056: 1975 | O1056: Aug | P1056: 21 | Q1056: =P1056&"-"&O1056&"-"&N1056 -> 21-Aug-1975 | R1056: =DATEDIF(Q1056,"8-6-2023","y") -> 47 | S1056: 8556.91
A1057: Id1056 | B1057: Clason, Ms. Gillian | C1057: Ms | D1057: Gillian | E1057: Clason | G1057: 0 | H1057: No | I1057: No | J1057: 35.34 | K1057: {=_xlfn.IFS(J1057<18.5,"underweight",J1057<25,"normal weight",J1057<30,"overweight",J1057>30,"obesity")} -> obesity | L1057: 4.13 | M1057: {=_xlfn.IFS(L1057<5.7,"Normal",L1057<6.5,"Prediabetes",L1057>6.5,"Diabetes")} -> Normal | N1057: 1988 | O1057: Sep | P1057: 21 | Q1057: =P1057&"-"&O1057&"-"&N1057 -> 21-Sep-1988 | R1057: =DATEDIF(Q1057,"8-6-2023","y") -> 34 | S1057: 8567.25
A1058: Id1057 | B1058: Donnelly, Mrs. Brenn E. | C1058: Mrs | D1058: Brenn E | E1058: Donnelly | G1058: 1 | H1058: No | I1058: No | J1058: 26.695 | K1058: {=_xlfn.IFS(J1058<18.5,"underweight",J1058<25,"normal weight",J1058<30,"overweight",J1058>30,"obesity")} -> overweight | L1058: 5.28 | M1058: {=_xlfn.IFS(L1058<5.7,"Normal",L1058<6.5,"Prediabetes",L1058>6.5,"Diabetes")} -> Normal | N1058: 1975 | O1058: Sep | P1058: 26 | Q1058: =P1058&"-"&O1058&"-"&N1058 -> 26-Sep-1975 | R1058: =DATEDIF(Q1058,"8-6-2023","y") -> 47 | S1058: 8569.86
A1059: Id1058 | B1059: Pietz, Ms. Lisa M | C1059: Ms | D1059: Lisa M | E1059: Pietz | G1059: 0 | H1059: No | I1059: No | J1059: 29.59 | K1059: {=_xlfn.IFS(J1059<18.5,"underweight",J1059<25,"normal weight",J1059<30,"overweight",J1059>30,"obesity")} -> overweight | L1059: 4.06 | M1059: {=_xlfn.IFS(L1059<5.7,"Normal",L1059<6.5,"Prediabetes",L1059>6.5,"Diabetes")} -> Normal | N1059: 1982 | O1059: Dec | P1059: 6 | Q1059: =P1059&"-"&O1059&"-"&N1059 -> 6-Dec-1982 | R1059: =DATEDIF(Q1059,"8-6-2023","y") -> 40 | S1059: 8572.04
A1060: Id1059 | B1060: Tegenkamp, Mr. Matt | C1060: Mr | D1060: Matt | E1060: Tegenkamp | G1060: 2 | H1060: No | I1060: No | J1060: 31.35 | K1060: {=_xlfn.IFS(J1060<18.5,"underweight",J1060<25,"normal weight",J1060<30,"overweight",J1060>30,"obesity")} -> obesity | L1060: 4.2 | M1060: {=_xlfn.IFS(L1060<5.7,"Normal",L1060<6.5,"Prediabetes",L1060>6.5,"Diabetes")} -> Normal | N1060: 1987 | O1060: Nov | P1060: 11 | Q1060: =P1060&"-"&O1060&"-"&N1060 -> 11-Nov-1987 | R1060: =DATEDIF(Q1060,"8-6-2023","y") -> 35 | S1060: 8573.3
A1061: Id1060 | B1061: Dover, Mr. Thomas A. | C1061: Mr | D1061: Thomas A | E1061: Dover | G1061: 0 | H1061: No | I1061: No | J1061: 20.52 | K1061: {=_xlfn.IFS(J1061<18.5,"underweight",J1061<25,"normal weight",J1061<30,"overweight",J1061>30,"obesity")} -> normal weight | L1061: 4.83 | M1061: {=_xlfn.IFS(L1061<5.7,"Normal",L1061<6.5,"Prediabetes",L1061>6.5,"Diabetes")} -> Normal | N1061: 1983 | O1061: Dec | P1061: 30 | Q1061: =P1061&"-"&O1061&"-"&N1061 -> 30-Dec-1983 | R1061: =DATEDIF(Q1061,"8-6-2023","y") -> 39 | S1061: 8582.3
A1062: Id1061 | B1062: Dockemeyer, Mr. Kevin J | C1062: Mr | D1062: Kevin J | E1062: Dockemeyer | G1062: 2 | H1062: No | I1062: No | J1062: 24.6 | K1062: {=_xlfn.IFS(J1062<18.5,"underweight",J1062<25,"normal weight",J1062<30,"overweight",J1062>30,"obesity")} -> normal weight | L1062: 5.86 | M1062: {=_xlfn.IFS(L1062<5.7,"Normal",L1062<6.5,"Prediabetes",L1062>6.5,"Diabetes")} -> Prediabetes | N1062: 1983 | O1062: Jul | P1062: 25 | Q1062: =P1062&"-"&O1062&"-"&N1062 -> 25-Jul-1983 | R1062: =DATEDIF(Q1062,"8-6-2023","y") -> 40 | S1062: 8596.83
A1063: Id1062 | B1063: Steele, Mr. William H. III | C1063: Mr | D1063: William H | E1063: Steele | G1063: 2 | H1063: No | I1063: No | J1063: 28.405 | K1063: {=_xlfn.IFS(J1063<18.5,"underweight",J1063<25,"normal weight",J1063<30,"overweight",J1063>30,"obesity")} -> overweight | L1063: 4.12 | M1063: {=_xlfn.IFS(L1063<5.7,"Normal",L1063<6.5,"Prediabetes",L1063>6.5,"Diabetes")} -> Normal | N1063: 1973 | O1063: Jul | P1063: 11 | Q1063: =P1063&"-"&O1063&"-"&N1063 -> 11-Jul-1973 | R1063: =DATEDIF(Q1063,"8-6-2023","y") -> 50 | S1063: 8601.33
A1064: Id1063 | B1064: Harel, Mr. Gal | C1064: Mr | D1064: Gal | E1064: Harel | G1064: 0 | H1064: No | I1064: No | J1064: 18.85 | K1064: {=_xlfn.IFS(J1064<18.5,"underweight",J1064<25,"normal weight",J1064<30,"overweight",J1064>30,"obesity")} -> normal weight | L1064: 6.03 | M1064: {=_xlfn.IFS(L1064<5.7,"Normal",L1064<6.5,"Prediabetes",L1064>6.5,"Diabetes")} -> Prediabetes | N1064: 1977 | O1064: Sep | P1064: 24 | Q1064: =P1064&"-"&O1064&"-"&N1064 -> 24-Sep-1977 | R1064: =DATEDIF(Q1064,"8-6-2023","y") -> 45 | S1064: 8603.82
A1065: Id1064 | B1065: Aguila, Mr. Anton | C1065: Mr | D1065: Anton | E1065: Aguila | G1065: 2 | H1065: No | I1065: No | J1065: 34.13 | K1065: {=_xlfn.IFS(J1065<18.5,"underweight",J1065<25,"normal weight",J1065<30,"overweight",J1065>30,"obesity")} -> obesity | L1065: 5.65 | M1065: {=_xlfn.IFS(L1065<5.7,"Normal",L1065<6.5,"Prediabetes",L1065>6.5,"Diabetes")} -> Normal | N1065: 1977 | O1065: Nov | P1065: 12 | Q1065: =P1065&"-"&O1065&"-"&N1065 -> 12-Nov-1977 | R1065: =DATEDIF(Q1065,"8-6-2023","y") -> 45 | S1065: 8604.48
A1066: Id1065 | B1066: Vallejo Sarmiento, Ms. Yazmin | C1066: Ms | D1066: Yazmin | E1066: Vallejo Sarmiento | G1066: 1 | H1066: No | I1066: No | J1066: 17.34 | K1066: {=_xlfn.IFS(J1066<18.5,"underweight",J1066<25,"normal weight",J1066<30,"overweight",J1066>30,"obesity")} -> underweight | L1066: 5.05 | M1066: {=_xlfn.IFS(L1066<5.7,"Normal",L1066<6.5,"Prediabetes",L1066>6.5,"Diabetes")} -> Normal | N1066: 1977 | O1066: Oct | P1066: 15 | Q1066: =P1066&"-"&O1066&"-"&N1066 -> 15-Oct-1977 | R1066: =DATEDIF(Q1066,"8-6-2023","y") -> 45 | S1066: 8605.36
... A2336: Id2335 | B2336: German, Mr. Aaron K | C2336: Mr | D2336: Aaron K | E2336: German | G2336: 1 | H2336: yes | I2336: No | J2336: 22.24 | K2336: {=_xlfn.IFS(J2336<18.5,"underweight",J2336<25,"normal weight",J2336<30,"overweight",J2336>30,"obesity")} -> normal weight | L2336: 4.29 | M2336: {=_xlfn.IFS(L2336<5.7,"Normal",L2336<6.5,"Prediabetes",L2336>6.5,"Diabetes")} -> Normal | N2336: 1963 | O2336: Sep | P2336: 4 | Q2336: =P2336&"-"&O2336&"-"&N2336 -> 4-Sep-1963 | R2336: =DATEDIF(Q2336,"8-6-2023","y") -> 59 | S2336: 48970.25
N2337: 1958 | O2337: Jun | P2337: 27 | Q2337: =P2337&"-"&O2337&"-"&N2337 -> 27-Jun-1958 | R2337: =DATEDIF(Q2337,"8-6-2023","y") -> 65 | S2337: 49577.66
N2338: 1994 | O2338: Oct | P2338: 27 | Q2338: =P2338&"-"&O2338&"-"&N2338 -> 27-Oct-1994 | R2338: =DATEDIF(Q2338,"8-6-2023","y") -> 28 | S2338: 51194.56
N2339: 1962 | O2339: Aug | P2339: 4 | Q2339: =P2339&"-"&O2339&"-"&N2339 -> 4-Aug-1962 | R2339: =DATEDIF(Q2339,"8-6-2023","y") -> 61 | S2339: 52590.83
N2340: 1989 | O2340: Jun | P2340: 19 | Q2340: =P2340&"-"&O2340&"-"&N2340 -> 19-Jun-1989 | R2340: =DATEDIF(Q2340,"8-6-2023","y") -> 34 | S2340: 55135.4
N2341: 1991 | O2341: Jun | P2341: 6 | Q2341: =P2341&"-"&O2341&"-"&N2341 -> 6-Jun-1991 | R2341: =DATEDIF(Q2341,"8-6-2023","y") -> 32 | S2341: 58571.07
N2342: 1970 | O2342: ? | P2342: 11 | Q2342: =P2342&"-"&O2342&"-"&N2342 -> 11-?-1970 | R2342: =DATEDIF(Q2342,"8-6-2023","y") -> #VALUE! | S2342: 60021.4
N2343: 1977 | O2343: Jun | P2343: 8 | Q2343: =P2343&"-"&O2343&"-"&N2343 -> 8-Jun-1977 | R2343: =DATEDIF(Q2343,"8-6-2023","y") -> 46 | S2343: 62592.87
N2344: 1968 | O2344: Oct | P2344: 12 | Q2344: =P2344&"-"&O2344&"-"&N2344 -> 12-Oct-1968 | R2344: =DATEDIF(Q2344,"8-6-2023","y") -> 54 | S2344: 63770.43

Sheet health care
A1: Customer ID | B1: Name | C1: BMI | D1: HBA1C | E1: Heart Issues | F1: Any Transplants | G1: Cancer history | H1: NumberOfMajorSurgeries | I1: smoker | J1: weight status | K1: Diabetes Status | L1: Date of Birth | M1: charges | N1: Hospital tier | O1: City tier | P1: State ID | Q1: Age
A2: Id1 | B2: =VLOOKUP($A2,'Data Transformation'!$A$2:$D$2336,4,) -> Kelly | C2: =VLOOKUP($A2,'Medical Examinations'!$A$2:$B$2336,2,) -> 47.41 | D2: =VLOOKUP($A2,'Medical Examinations'!$A$2:$C$2336,3,) -> 7.47 | E2: =VLOOKUP($A2,'Medical Examinations'!$A$2:$D$2336,4,) -> No | F2: =VLOOKUP($A2,'Medical Examinations'!$A$2:$E$2336,5,) -> No | G2: =VLOOKUP($A2,'Medical Examinations'!$A$2:$F$2336,6,) -> No | H2: =VLOOKUP($A2,'Data Transformation'!$A$2:$G$2336,7,) -> 0 | I2: =VLOOKUP($A2,'Medical Examinations'!$A$2:$H$2336,8,) -> yes | J2: =VLOOKUP($A2,'Data Transformation'!$A$2:$K$2336,11,) -> obesity | K2: =VLOOKUP($A2,'Data Transformation'!$A$2:$M$2336,13,) -> Diabetes | L2: =VLOOKUP(A2,'Data Transformation'!A2:Q2336,17,) -> 9-Jul-1992 | M2: =VLOOKUP($A2,'Hospitalisation Details'!$A$2:$I$2344,6,) -> 63770.43 | N2: =VLOOKUP($A2,'Hospitalisation Details'!$A$2:$I$2344,7,) -> tier - 1 | O2: =VLOOKUP($A2,'Hospitalisation Details'!$A$2:$I$2344,8,) -> tier - 3 | P2: =VLOOKUP($A2,'Hospitalisation Details'!$A$2:$I$2344,9,) -> R1013 | Q2: =VLOOKUP(A2,'Data Transformation'!A2:R2336,18,) -> 31
A3: Id2 | B3: =VLOOKUP($A3,'Data Transformation'!$A$2:$D$2336,4,) -> Matthew D | C3: =VLOOKUP($A3,'Medical Examinations'!$A$2:$B$2336,2,) -> 30.36 | D3: =VLOOKUP($A3,'Medical Examinations'!$A$2:$C$2336,3,) -> 5.77 | E3: =VLOOKUP($A3,'Medical Examinations'!$A$2:$D$2336,4,) -> No | F3: =VLOOKUP($A3,'Medical Examinations'!$A$2:$E$2336,5,) -> No | G3: =VLOOKUP($A3,'Medical Examinations'!$A$2:$F$2336,6,) -> No | H3: =VLOOKUP($A3,'Data Transformation'!$A$2:$G$2336,7,) -> 0 | I3: =VLOOKUP($A3,'Medical Examinations'!$A$2:$H$2336,8,) -> yes | J3: =VLOOKUP($A3,'Data Transformation'!$A$2:$K$2336,11,) -> obesity | K3: =VLOOKUP($A3,'Data Transformation'!$A$2:$M$2336,13,) -> Prediabetes | L3: =VLOOKUP(A3,'Data Transformation'!A3:Q2337,17,) -> 30-Nov-1992 | M3: =VLOOKUP($A3,'Hospitalisation Details'!$A$2:$I$2344,6,) -> 62592.87 | N3: =VLOOKUP($A3,'Hospitalisation Details'!$A$2:$I$2344,7,) -> tier - 2 | O3: =VLOOKUP($A3,'Hospitalisation Details'!$A$2:$I$2344,8,) -> tier - 3 | P3: =VLOOKUP($A3,'Hospitalisation Details'!$A$2:$I$2344,9,) -> R1013 | Q3: =VLOOKUP(A3,'Data Transformation'!A3:R2337,18,) -> 30
A4: Id3 | B4: =VLOOKUP($A4,'Data Transformation'!$A$2:$D$2336,4,) -> Phil | C4: =VLOOKUP($A4,'Medical Examinations'!$A$2:$B$2336,2,) -> 34.485 | D4: =VLOOKUP($A4,'Medical Examinations'!$A$2:$C$2336,3,) -> 11.87 | E4: =VLOOKUP($A4,'Medical Examinations'!$A$2:$D$2336,4,) -> yes | F4: =VLOOKUP($A4,'Medical Examinations'!$A$2:$E$2336,5,) -> No | G4: =VLOOKUP($A4,'Medical Examinations'!$A$2:$F$2336,6,) -> No | H4: =VLOOKUP($A4,'Data Transformation'!$A$2:$G$2336,7,) -> 2 | I4: =VLOOKUP($A4,'Medical Examinations'!$A$2:$H$2336,8,) -> yes | J4: =VLOOKUP($A4,'Data Transformation'!$A$2:$K$2336,11,) -> obesity | K4: =VLOOKUP($A4,'Data Transformation'!$A$2:$M$2336,13,) -> Prediabetes | L4: =VLOOKUP(A4,'Data Transformation'!A4:Q2338,17,) -> 30-Jun-1993 | M4: =VLOOKUP($A4,'Hospitalisation Details'!$A$2:$I$2344,6,) -> 60021.4 | N4: =VLOOKUP($A4,'Hospitalisation Details'!$A$2:$I$2344,7,) -> tier - 1 | O4: =VLOOKUP($A4,'Hospitalisation Details'!$A$2:$I$2344,8,) -> tier - 1 | P4: =VLOOKUP($A4,'Hospitalisation Details'!$A$2:$I$2344,9,) -> R1012 | Q4: =VLOOKUP(A4,'Data Transformation'!A4:R2338,18,) -> 30
A5: Id4 | B5: =VLOOKUP($A5,'Data Transformation'!$A$2:$D$2336,4,) -> Kelsey | C5: =VLOOKUP($A5,'Medical Examinations'!$A$2:$B$2336,2,) -> 38.095 | D5: =VLOOKUP($A5,'Medical Examinations'!$A$2:$C$2336,3,) -> 6.05 | E5: =VLOOKUP($A5,'Medical Examinations'!$A$2:$D$2336,4,) -> No | F5: =VLOOKUP($A5,'Medical Examinations'!$A$2:$E$2336,5,) -> No | G5: =VLOOKUP($A5,'Medical Examinations'!$A$2:$F$2336,6,) -> No | H5: =VLOOKUP($A5,'Data Transformation'!$A$2:$G$2336,7,) -> 0 | I5: =VLOOKUP($A5,'Medical Examinations'!$A$2:$H$2336,8,) -> yes | J5: =VLOOKUP($A5,'Data Transformation'!$A$2:$K$2336,11,) -> obesity | K5: =VLOOKUP($A5,'Data Transformation'!$A$2:$M$2336,13,) -> Normal | L5: =VLOOKUP(A5,'Data Transformation'!A5:Q2339,17,) -> 13-Sep-1992 | M5: =VLOOKUP($A5,'Hospitalisation Details'!$A$2:$I$2344,6,) -> 58571.07 | N5: =VLOOKUP($A5,'Hospitalisation Details'!$A$2:$I$2344,7,) -> tier - 1 | O5: =VLOOKUP($A5,'Hospitalisation Details'!$A$2:$I$2344,8,) -> tier - 3 | P5: =VLOOKUP($A5,'Hospitalisation Details'!$A$2:$I$2344,9,) -> R1024 | Q5: =VLOOKUP(A5,'Data Transformation'!A5:R2339,18,) -> 30
A6: Id5 | B6: =VLOOKUP($A6,'Data Transformation'!$A$2:$D$2336,4,) -> Kristyn | C6: =VLOOKUP($A6,'Medical Examinations'!$A$2:$B$2336,2,) -> 35.53 | D6: =VLOOKUP($A6,'Medical Examinations'!$A$2:$C$2336,3,) -> 5.45 | E6: =VLOOKUP($A6,'Medical Examinations'!$A$2:$D$2336,4,) -> No | F6: =VLOOKUP($A6,'Medical Examinations'!$A$2:$E$2336,5,) -> No | G6: =VLOOKUP($A6,'Medical Examinations'!$A$2:$F$2336,6,) -> No | H6: =VLOOKUP($A6,'Data Transformation'!$A$2:$G$2336,7,) -> 0 | I6: =VLOOKUP($A6,'Medical Examinations'!$A$2:$H$2336,8,) -> yes | J6: =VLOOKUP($A6,'Data Transformation'!$A$2:$K$2336,11,) -> obesity | K6: =VLOOKUP($A6,'Data Transformation'!$A$2:$M$2336,13,) -> Diabetes | L6: =VLOOKUP(A6,'Data Transformation'!A6:Q2340,17,) -> 27-Jul-1998 | M6: =VLOOKUP($A6,'Hospitalisation Details'!$A$2:$I$2344,6,) -> 55135.4 | N6: =VLOOKUP($A6,'Hospitalisation Details'!$A$2:$I$2344,7,) -> tier - 1 | O6: =VLOOKUP($A6,'Hospitalisation Details'!$A$2:$I$2344,8,) -> tier - 2 | P6: =VLOOKUP($A6,'Hospitalisation Details'!$A$2:$I$2344,9,) -> R1012 | Q6: =VLOOKUP(A6,'Data Transformation'!A6:R2340,18,) -> 25
A7: Id6 | B7: =VLOOKUP($A7,'Data Transformation'!$A$2:$D$2336,4,) -> Russell B | C7: =VLOOKUP($A7,'Medical Examinations'!$A$2:$B$2336,2,) -> 32.8 | D7: =VLOOKUP($A7,'Medical Examinations'!$A$2:$C$2336,3,) -> 6.59 | E7: =VLOOKUP($A7,'Medical Examinations'!$A$2:$D$2336,4,) -> No | F7: =VLOOKUP($A7,'Medical Examinations'!$A$2:$E$2336,5,) -> No | G7: =VLOOKUP($A7,'Medical Examinations'!$A$2:$F$2336,6,) -> No | H7: =VLOOKUP($A7,'Data Transformation'!$A$2:$G$2336,7,) -> 0 | I7: =VLOOKUP($A7,'Medical Examinations'!$A$2:$H$2336,8,) -> yes | J7: =VLOOKUP($A7,'Data Transformation'!$A$2:$K$2336,11,) -> obesity | K7: =VLOOKUP($A7,'Data Transformation'!$A$2:$M$2336,13,) -> Prediabetes | L7: =VLOOKUP(A7,'Data Transformation'!A7:Q2341,17,) -> 20-Nov-2001 | M7: =VLOOKUP($A7,'Hospitalisation Details'!$A$2:$I$2344,6,) -> 52590.83 | N7: =VLOOKUP($A7,'Hospitalisation Details'!$A$2:$I$2344,7,) -> tier - 1 | O7: =VLOOKUP($A7,'Hospitalisation Details'!$A$2:$I$2344,8,) -> tier - 3 | P7: =VLOOKUP($A7,'Hospitalisation Details'!$A$2:$I$2344,9,) -> R1011 | Q7: =VLOOKUP(A7,'Data Transformation'!A7:R2341,18,) -> 21
A8: Id7 | B8: =VLOOKUP($A8,'Data Transformation'!$A$2:$D$2336,4,) -> Scott | C8: =VLOOKUP($A8,'Medical Examinations'!$A$2:$B$2336,2,) -> 36.4 | D8: =VLOOKUP($A8,'Medical Examinations'!$A$2:$C$2336,3,) -> 6.07 | E8: =VLOOKUP($A8,'Medical Examinations'!$A$2:$D$2336,4,) -> No | F8: =VLOOKUP($A8,'Medical Examinations'!$A$2:$E$2336,5,) -> No | G8: =VLOOKUP($A8,'Medical Examinations'!$A$2:$F$2336,6,) -> No | H8: =VLOOKUP($A8,'Data Transformation'!$A$2:$G$2336,7,) -> 0 | I8: =VLOOKUP($A8,'Medical Examinations'!$A$2:$H$2336,8,) -> yes | J8: =VLOOKUP($A8,'Data Transformation'!$A$2:$K$2336,11,) -> obesity | K8: =VLOOKUP($A8,'Data Transformation'!$A$2:$M$2336,13,) -> Diabetes | L8: =VLOOKUP(A8,'Data Transformation'!A8:Q2342,17,) -> 1-Jun-1993 | M8: =VLOOKUP($A8,'Hospitalisation Details'!$A$2:$I$2344,6,) -> 51194.56 | N8: =VLOOKUP($A8,'Hospitalisation Details'!$A$2:$I$2344,7,) -> tier - 1 | O8: =VLOOKUP($A8,'Hospitalisation Details'!$A$2:$I$2344,8,) -> tier - 3 | P8: =VLOOKUP($A8,'Hospitalisation Details'!$A$2:$I$2344,9,) -> R1011 | Q8: =VLOOKUP(A8,'Data Transformation'!A8:R2342,18,) -> 30
A9: Id8 | B9: =VLOOKUP($A9,'Data Transformation'!$A$2:$D$2336,4,) -> Stephen | C9: =VLOOKUP($A9,'Medical Examinations'!$A$2:$B$2336,2,) -> 36.96 | D9: =VLOOKUP($A9,'Medical Examinations'!$A$2:$C$2336,3,) -> 7.93 | E9: =VLOOKUP($A9,'Medical Examinations'!$A$2:$D$2336,4,) -> No | F9: =VLOOKUP($A9,'Medical Examinations'!$A$2:$E$2336,5,) -> No | G9: =VLOOKUP($A9,'Medical Examinations'!$A$2:$F$2336,6,) -> No | H9: =VLOOKUP($A9,'Data Transformation'!$A$2:$G$2336,7,) -> 3 | I9: =VLOOKUP($A9,'Medical Examinations'!$A$2:$H$2336,8,) -> yes | J9: =VLOOKUP($A9,'Data Transformation'!$A$2:$K$2336,11,) -> obesity | K9: =VLOOKUP($A9,'Data Transformation'!$A$2:$M$2336,13,) -> Diabetes | L9: =VLOOKUP(A9,'Data Transformation'!A9:Q2343,17,) -> 4-Jul-1995 | M9: =VLOOKUP($A9,'Hospitalisation Details'!$A$2:$I$2344,6,) -> 49577.66 | N9: =VLOOKUP($A9,'Hospitalisation Details'!$A$2:$I$2344,7,) -> tier - 2 | O9: =VLOOKUP($A9,'Hospitalisation Details'!$A$2:$I$2344,8,) -> tier - 2 | P9: =VLOOKUP($A9,'Hospitalisation Details'!$A$2:$I$2344,9,) -> R1013 | Q9: =VLOOKUP(A9,'Data Transformation'!A9:R2343,18,) -> 28
A10: Id9 | B10: =VLOOKUP($A10,'Data Transformation'!$A$2:$D$2336,4,) -> Patrick R | C10: =VLOOKUP($A10,'Medical Examinations'!$A$2:$B$2336,2,) -> 41.14 | D10: =VLOOKUP($A10,'Medical Examinations'!$A$2:$C$2336,3,) -> 9.58 | E10: =VLOOKUP($A10,'Medical Examinations'!$A$2:$D$2336,4,) -> yes | F10: =VLOOKUP($A10,'Medical Examinations'!$A$2:$E$2336,5,) -> No | G10: =VLOOKUP($A10,'Medical Examinations'!$A$2:$F$2336,6,) -> Yes | H10: =VLOOKUP($A10,'Data Transformation'!$A$2:$G$2336,7,) -> 1 | I10: =VLOOKUP($A10,'Medical Examinations'!$A$2:$H$2336,8,) -> yes | J10: =VLOOKUP($A10,'Data Transformation'!$A$2:$K$2336,11,) -> obesity | K10: =VLOOKUP($A10,'Data Transformation'!$A$2:$M$2336,13,) -> Diabetes | L10: =VLOOKUP(A10,'Data Transformation'!A10:Q2344,17,) -> 29-Nov-2002 | M10: =VLOOKUP($A10,'Hospitalisation Details'!$A$2:$I$2344,6,) -> 48970.25 | N10: =VLOOKUP($A10,'Hospitalisation Details'!$A$2:$I$2344,7,) -> tier - 1 | O10: =VLOOKUP($A10,'Hospitalisation Details'!$A$2:$I$2344,8,) -> tier - 2 | P10: =VLOOKUP($A10,'Hospitalisation Details'!$A$2:$I$2344,9,) -> R1013 | Q10: =VLOOKUP(A10,'Data Transformation'!A10:R2344,18,) -> 20
A11: Id10 | B11: =VLOOKUP($A11,'Data Transformation'!$A$2:$D$2336,4,) -> Brooke N | C11: =VLOOKUP($A11,'Medical Examinations'!$A$2:$B$2336,2,) -> 38.06 | D11: =VLOOKUP($A11,'Medical Examinations'!$A$2:$C$2336,3,) -> 10.79 | E11: =VLOOKUP($A11,'Medical Examinations'!$A$2:$D$2336,4,) -> No | F11: =VLOOKUP($A11,'Medical Examinations'!$A$2:$E$2336,5,) -> No | G11: =VLOOKUP($A11,'Medical Examinations'!$A$2:$F$2336,6,) -> No | H11: =VLOOKUP($A11,'Data Transformation'!$A$2:$G$2336,7,) -> 0 | I11: =VLOOKUP($A11,'Medical Examinations'!$A$2:$H$2336,8,) -> yes | J11: =VLOOKUP($A11,'Data Transformation'!$A$2:$K$2336,11,) -> obesity | K11: =VLOOKUP($A11,'Data Transformation'!$A$2:$M$2336,13,) -> Diabetes | L11: =VLOOKUP(A11,'Data Transformation'!A11:Q2345,17,) -> 9-Nov-1997 | M11: =VLOOKUP($A11,'Hospitalisation Details'!$A$2:$I$2344,6,) -> 48885.14 | N11: =VLOOKUP($A11,'Hospitalisation Details'!$A$2:$I$2344,7,) -> tier - 1 | O11: =VLOOKUP($A11,'Hospitalisation Details'!$A$2:$I$2344,8,) -> tier - 2 | P11: =VLOOKUP($A11,'Hospitalisation Details'!$A$2:$I$2344,9,) -> R1013 | Q11: =VLOOKUP(A11,'Data Transformation'!A11:R2345,18,) -> 25
A12: Id11 | B12: =VLOOKUP($A12,'Data Transformation'!$A$2:$D$2336,4,) -> Paola Andrea | C12: =VLOOKUP($A12,'Medical Examinations'!$A$2:$B$2336,2,) -> 37.7 | D12: =VLOOKUP($A12,'Medical Examinations'!$A$2:$C$2336,3,) -> 5.96 | E12: =VLOOKUP($A12,'Medical Examinations'!$A$2:$D$2336,4,) -> yes | F12: =VLOOKUP($A12,'Medical Examinations'!$A$2:$E$2336,5,) -> No | G12: =VLOOKUP($A12,'Medical Examinations'!$A$2:$F$2336,6,) -> No | H12: =VLOOKUP($A12,'Data Transformation'!$A$2:$G$2336,7,) -> 2 | I12: =VLOOKUP($A12,'Medical Examinations'!$A$2:$H$2336,8,) -> yes | J12: =VLOOKUP($A12,'Data Transformation'!$A$2:$K$2336,11,) -> obesity | K12: =VLOOKUP($A12,'Data Transformation'!$A$2:$M$2336,13,) -> Diabetes | L12: =VLOOKUP(A12,'Data Transformation'!A12:Q2346,17,) -> 12-Sep-2001 | M12: =VLOOKUP($A12,'Hospitalisation Details'!$A$2:$I$2344,6,) -> 48824.45 | N12: =VLOOKUP($A12,'Hospitalisation Details'!$A$2:$I$2344,7,) -> tier - 2 | O12: =VLOOKUP($A12,'Hospitalisation Details'!$A$2:$I$2344,8,) -> tier - 1 | P12: =VLOOKUP($A12,'Hospitalisation Details'!$A$2:$I$2344,9,) -> R1011 | Q12: =VLOOKUP(A12,'Data Transformation'!A12:R2346,18,) -> 21
A13: Id12 | B13: =VLOOKUP($A13,'Data Transformation'!$A$2:$D$2336,4,) -> David | C13: =VLOOKUP($A13,'Medical Examinations'!$A$2:$B$2336,2,) -> 42.13 | D13: =VLOOKUP($A13,'Medical Examinations'!$A$2:$C$2336,3,) -> 11.9 | E13: =VLOOKUP($A13,'Medical Examinations'!$A$2:$D$2336,4,) -> No | F13: =VLOOKUP($A13,'Medical Examinations'!$A$2:$E$2336,5,) -> No | G13: =VLOOKUP($A13,'Medical Examinations'!$A$2:$F$2336,6,) -> No | H13: =VLOOKUP($A13,'Data Transformation'!$A$2:$G$2336,7,) -> 0 | I13: =VLOOKUP($A13,'Medical Examinations'!$A$2:$H$2336,8,) -> yes | J13: =VLOOKUP($A13,'Data Transformation'!$A$2:$K$2336,11,) -> obesity | K13: =VLOOKUP($A13,'Data Transformation'!$A$2:$M$2336,13,) -> Diabetes | L13: =VLOOKUP(A13,'Data Transformation'!A13:Q2347,17,) -> 26-Dec-1999 | M13: =VLOOKUP($A13,'Hospitalisation Details'!$A$2:$I$2344,6,) -> 48675.52 | N13: =VLOOKUP($A13,'Hospitalisation Details'!$A$2:$I$2344,7,) -> tier - 1 | O13: =VLOOKUP($A13,'Hospitalisation Details'!$A$2:$I$2344,8,) -> tier - 2 | P13: =VLOOKUP($A13,'Hospitalisation Details'!$A$2:$I$2344,9,) -> R1013 | Q13: =VLOOKUP(A13,'Data Transformation'!A13:R2347,18,) -> 23
... A2336: Id2335 | B2336: =VLOOKUP($A2336,'Data Transformation'!$A$2:$D$2336,4,) -> Aaron K | C2336: =VLOOKUP($A2336,'Medical Examinations'!$A$2:$B$2336,2,) -> 17.58 | D2336: =VLOOKUP($A2336,'Medical Examinations'!$A$2:$C$2336,3,) -> 4.51 | E2336: =VLOOKUP($A2336,'Medical Examinations'!$A$2:$D$2336,4,) -> No | F2336: =VLOOKUP($A2336,'Medical Examinations'!$A$2:$E$2336,5,) -> No | G2336: =VLOOKUP($A2336,'Medical Examinations'!$A$2:$F$2336,6,) -> No | H2336: =VLOOKUP($A2336,'Data Transformation'!$A$2:$G$2336,7,) -> 1 | I2336: =VLOOKUP($A2336,'Medical Examinations'!$A$2:$H$2336,8,) -> No | J2336: =VLOOKUP($A2336,'Data Transformation'!$A$2:$K$2336,11,) -> normal weight | K2336: =VLOOKUP($A2336,'Data Transformation'!$A$2:$M$2336,13,) -> Normal | L2336: =VLOOKUP(A2336,'Data Transformation'!A2336:Q4670,17,) -> 4-Sep-1963 | M2336: =VLOOKUP($A2336,'Hospitalisation Details'!$A$2:$I$2344,6,) -> 563.84 | N2336: =VLOOKUP($A2336,'Hospitalisation Details'!$A$2:$I$2344,7,) -> tier - 2 | O2336: =VLOOKUP($A2336,'Hospitalisation Details'!$A$2:$I$2344,8,) -> tier - 3 | P2336: =VLOOKUP($A2336,'Hospitalisation Details'!$A$2:$I$2344,9,) -> R1013 | Q2336: =VLOOKUP(A2336,'Data Transformation'!A2336:R4670,18,) -> 59

Sheet pivot table
A3: Row Labels | B3: Count of smoker
A4: No | B4: 1944
A5: Yes | B5: 391
A6: Grand Total | B6: 2335
A12: Row Labels | B12: Average of HBA1C
A13: 0 | B13: 7.1031378
A14: 1 | B14: 5.811658
A15: 2 | B15: 7.0210949
A16: 3 | B16: 9.1436364
A17: Grand Total | B17: 6.5789979
A21: Row Labels | B21: Sum of charges | C21: Count of Diabetes Status
A22: normal weight | B22: 5090670.7 | C22: 437
A23: obesity | B23: 18764904 | C23: 1218
A24: overweight | B24: 6249151.3 | C24: 501
A25: underweight | B25: 1448534.3 | C25: 176
A26: #N/A | B26: 39098.5 | C26: 3
A27: Grand Total | B27: 31592359 | C27: #N/A
A30: Row Labels | B30: Average of charges
A31: tier - 1 | B31: 30129.199
A32: R1011 | B32: 33081.374
A33: R1012 | B33: 26111.458
A34: R1013 | B34: 31328.102
A35: R1014 | B35: 13891.86
A36: R1015 | B36: 21523.52
A37: R1016 | B37: 39868.616
A38: R1017 | B38: 34070.596
A39: R1018 | B39: 33475.82
A40: R1019 | B40: 27621.61
A41: R1023 | B41: 18261.757
A42: R1024 | B42: 32732.187
... A81: Grand Total | B81: 13529.918
A85: Row Labels | B85: Sum of BMI | C85: Sum of HBA1C
A86: 18 | B86: 2338.355 | C86: 451.69
A87: 19 | B87: 3281.27 | C87: 647.21
A88: 20 | B88: 1891.885 | C88: 396.19
A89: 21 | B89: 1656.82 | C89: 339.37
A90: 22 | B90: 1726.61 | C90: 339.2
A91: 23 | B91: 1664.405 | C91: 317.06
A92: 24 | B92: 1364.095 | C92: 267.39
A93: 25 | B93: 1913.24 | C93: 401.58
...

Sheet Dashboard creation
